# 异常

- **Error**是_程序无法处理_的错误，它是由JVM产生和抛出的，比如`OutOfMemoryError`、`ThreadDeath`等。这些异常发生时，JVM一般会选择线程终止。
- **Exception**是_程序本身可以处理_的异常，这种异常分两大类：运行时异常和非运行时异常。程序中应当尽可能处理这些异常。

## 运行时异常和非运行时异常

### Checked Exception
我们经常遇到的 IO 异常及 sql 异常就属于检查式异常。 对于这种异常，必须要进行`try-catch`或者`throw`。

### RuntimeException
我们可以不处理。 当出现这样的异常时， 总是由虚拟机接管。 比如： 我们从来没有人去处理过 NullPointerException 异常， 它就是运行时异常， 并且这种异常还是最常见的异常之一。

被检查的异常应该用 try-catch 块代码处理或用 throws 关键字抛出，不受检查的异常在程序中不要求被处理或用 throws 抛出；Exception 是所有被检查异常的基类，而 RuntimeException（是 Exception 的子类） 是所有不受检查异常的基类；被检查的异常适用于那些不是因程序引起的错误情况（如`FileNotFoundException`），而不被检查的异常通常都是由于糟糕的编程引起（如`NullPointerException`）。

## 异常种类

Throwable
1. Exception
	1. IOException
		1. EOFException
		2. FileNotFoundException
		3. MalformedURLException
		4. UnknownHostException
	2. **RuntimeException**
		1. ClassCastException
		2. ArithemeticException
		3. IllegalStateException
		4. IndexOutOfBoundsException
		5. NoSuchElementException
		6. NullPointerException	
	3. ClassNotFoundException
	4. CloneNotSupportException
2. Error
	1. AWTError
	2. VirtualMachineError	

- NullPointerException：当应用程序试图访问空对象时，则抛出该异常。
- SQLException：提供关于数据库访问错误或其他错误信息的异常。
- IndexOutOfBoundsException：指示某排序索引（例如对数组、字符串或向量的排序）超出范围时抛出。
- NumberFormatException：当应用程序试图将字符串转换成一种数值类型，但该字符串不能转换为适当格式时，抛出该异常。
- FileNotFoundException：当试图打开指定路径名表示的文件失败时，抛出此异常。
- IOException：当发生某种I/O异常时，抛出此异常。此类是失败或中断的I/O操作生成的异常的通用类。
- ClassCastException：当试图将对象强制转换为不是实例的子类时，抛出该异常。
- ArrayStoreException：试图将错误类型的对象存储到一个对象数组时抛出的异常。
- IllegalArgumentException：抛出的异常表明向方法传递了一个不合法或不正确的参数。
- ArithmeticException：当出现异常的运算条件时，抛出此异常。例如，一个整数“除以零”时，抛出此类的一个实例。
- NegativeArraySizeException：如果应用程序试图创建大小为负的数组，则抛出该异常。
- NoSuchMethodException：无法找到某一特定方法时，抛出该异常。
- SecurityException：由安全管理器抛出的异常，指示存在安全侵犯。
- UnsupportedOperationException：当不支持请求的操作时，抛出该异常。
- RuntimeExceptionRuntimeException：是那些可能在Java虚拟机正常运行期间抛出的异常的超类。
## Error

错误，所有变异时期的错误以及系统错误。

![][image-1]
# 异常的捕获
```java
``
/*
 * java面试题--如果catch里面有return语句，finally里面的代码还会执行吗？
 */
public class FinallyDemo2 {
    public static void main(String[] args) {
        System.out.println(getInt());
    }

    public static int getInt() {
        int a = 10;
        try {
            System.out.println(a / 0);
            a = 20;
        } catch (ArithmeticException e) {
            a = 30;
            return a;
            /*
             * return a 在程序执行到这一步的时候，这里不是return a 而是 return 30；这个返回路径就形成了
             * 但是呢，它发现后面还有finally，所以继续执行finally的内容，a=40
             * 再次回到以前的路径,继续走return 30，形成返回路径之后，这里的a就不是a变量了，而是常量30
             */
        } finally {
            a = 40;
        }

//      输出30
    }
}

/*
 * java面试题--如果catch里面有return语句，finally里面的代码还会执行吗？
 */
public class FinallyDemo2 {
    public static void main(String[] args) {
        System.out.println(getInt());
    }

    public static int getInt() {
        int a = 10;
        try {
            System.out.println(a / 0);
            a = 20;
        } catch (ArithmeticException e) {
            a = 30;
            return a;
            /*
             * return a 在程序执行到这一步的时候，这里不是return a 而是 return 30；这个返回路径就形成了
             * 但是呢，它发现后面还有finally，所以继续执行finally的内容，a=40
             * 再次回到以前的路径,继续走return 30，形成返回路径之后，这里的a就不是a变量了，而是常量30
             */
        } finally {
            a = 40;
            return a; //如果这样，就又重新形成了一条返回路径，由于只能通过1个return返回，所以这里直接返回40
        }

//      输出40
    }
}

```

[image-1]:	https://raw.githubusercontent.com/zhangpengnian/ImageRepository/master/img/20191011194717.png